<html>
  <head>
    <title></title>
  </head>
  <body>

    <script>
      //await命令后面的 Promise 对象如果变为reject状态，则reject的参数会被catch方法的回调函数接收到。
      //下面await语句前面没有return，但是reject方法的参数依然传入了catch方法的回调函数。这里如果在await前面加上return，效果是一样的。
      async function f1(params) {
        await Promise.reject('出错了');
      }

      f1()
        .then(v => console.log(v))
        .catch(e => console.log(e));//出错了

      //任何一个await语句后面的 Promise 对象变为reject状态，那么整个async函数都会中断执行。
      async function f2() {
        await Promise.reject('出错了1');
        await Promise.resolve('hello world');
      }

      f2()
        .then(v => console.log(v))
        .catch(e => console.log(e)); //出错了1

    //有时，我们希望即使前一个异步操作失败，也不要中断后面的异步操作。
    //这时可以将第一个await放在try...catch结构里面，这样不管这个异步操作是否成功，第二个await都会执行。

    async function f3() {
      try {
        await Promise.reject('出错了2');
      } catch(e) {
      }
      return await Promise.resolve('hello world');
    }

    f3()
      .then(v => console.log(v))
      .catch(e => console.log(e)); //hello world

    //另一种方法是await后面的 Promise 对象再跟一个catch方法，处理前面可能出现的错误。
    async function f4() {
      await Promise.reject('出错了5').catch(e => console.log(e));
      return await Promise.resolve('hello world');
    }

    f4()
      .then(v => console.log(v))
      .catch(e => console.log(e)); //'出错了5' 'hello world'

    //如果有多个await命令
    async function f4 () {
      try {
        const value1 = Promise.resolve('hello world');
        const value2 = Promise.reject(value1);
        const value3 = Promise,resolve(value2);
      }
      catch(e){}
    }

    //await命令后面的Promise对象，运行结果可能是rejected，所以最好把await命令放在try...catch代码块中

    
    </script>
  </body>
</html>