<!DOCTYPE html>
<html lang="en">
<head>
    <meta charset="UTF-8">
    <title></title>
</head>
<body>

<script>
  //Promise.prototype.catch方法是.then(null, rejection)的别名，用于指定发生错误时的回调函数。
  //then链式之中任何一个抛出的错误，都会被最后一个catch捕获。
  //一般来说，不要在then方法里面定义 Reject 状态的回调函数（即then的第二个参数），总是使用catch方法。
  //跟传统的try/catch代码块不同的是，如果没有使用catch方法指定错误处理的回调函数，Promise 对象抛出的错误不会传递到外层代码，即不会不会退出进程、终止脚本执行。

  const promise = () => {
    return new Promise((resolve, reject) => {
      setTimeout(() => resolve(), 2000);
    })
  }

  const promise1 = () => {
    return new Promise((resolve, reject) => {
      setTimeout(() => reject(new Error('错误！')), 2000);
    })
  }

  promise()
    .then(() => {
      console.log('1');
      return promise();
    })
    .then(() => {
      console.log('2');
      return promise1();
    })
    .then(() => {
      console.log('3');
      return promise();
    })
    .catch((error) => {
      console.log('4');
      console.log('error', error);
    })

    //1
    //2
    //4
    //'error' Error: 错误！

    //promise抛出错误的写法
    
    //写法一
    const promise3 = new Promise((resolve, reject) => {
      throw new Error('test');
    })

    promise3.catch(error => console.log(error)); //Error: test

    //写法二
    const promise4 = new Promise((resolve, reject) => {
      try {
        throw new Error('test1');
      } catch(e) {
        reject(e);
      }
    });

    promise4.catch(error => console.log(error)); //Error: test1

    //写法二
    const promise5 = new Promise((resolve, reject) => {
      reject(new Error('test2'));
    })

    promise5.catch(error => console.log(error)); //Error: test2

    //如果 Promise 状态已经变成resolved，再抛出错误是无效的。
    const promise6 = new Promise((resolve, reject) => {
      resolve('ok');
      throw new Error('test3');
    })

    promise6
      .then(value => console.log(value))
      .catch(error => console.log(error)); //'ok'
</script>
</body>
</html>